cloudbridge.test.test_cloud_factory.CloudFactoryTestCase


Test output
 ...F.....
======================================================================
FAIL: test_find_provider_include_mocks (cloudbridge.test.test_cloud_factory.CloudFactoryTestCase)
----------------------------------------------------------------------
Traceback (most recent call last):
  File "/Users/alex/Desktop/work/cloudbridge/cloudbridge/test/test_cloud_factory.py", line 44, in test_find_provider_include_mocks
    "expected to find at least one mock provider")
AssertionError: False is not true : expected to find at least one mock provider

----------------------------------------------------------------------
Ran 9 tests in 1.887s

FAILED (failures=1)

Wrote profile results to run_single.py.lprof
Timer unit: 1e-06 s

